Workbook

Sheet Данные
A1: Номер студента | B1: Сумма | C1: Курс | D1: Время | E1: Дата
A2: 437 | B2: 8950 | C2: ML про | D2: 46238.381 | E2: =CaseDataTable[[#This Row],[Время]] -> 46238.381 | H2: Важные сведения
A3: 437 | B3: 7890 | C3: Аналитика старт | D3: 46238.399 | E3: =CaseDataTable[[#This Row],[Время]] -> 46238.399
A4: 443 | B4: 8475 | C4: Линейная алгебра | D4: 46238.427 | E4: =CaseDataTable[[#This Row],[Время]] -> 46238.427
A5: 443 | B5: 8475 | C5: Мат анализ | D5: 46238.427 | E5: =CaseDataTable[[#This Row],[Время]] -> 46238.427
A6: 430 | B6: 8950 | C6: К ВУЗу | D6: 46238.568 | E6: =CaseDataTable[[#This Row],[Время]] -> 46238.568
A7: 480 | B7: 15695 | C7: Data Science | D7: 46238.679 | E7: =CaseDataTable[[#This Row],[Время]] -> 46238.679
A8: 131 | B8: 8745 | C8: Backend старт | D8: 46238.712 | E8: =CaseDataTable[[#This Row],[Время]] -> 46238.712
A9: 571 | B9: 8475 | C9: ML про | D9: 46238.722 | E9: =CaseDataTable[[#This Row],[Время]] -> 46238.722
A10: 571 | B10: 8475 | C10: ML старт | D10: 46238.722 | E10: =CaseDataTable[[#This Row],[Время]] -> 46238.722
A11: 159 | B11: 8475 | C11: Backend про | D11: 46239.539 | E11: =CaseDataTable[[#This Row],[Время]] -> 46239.539
A12: 159 | B12: 8475 | C12: Backend старт | D12: 46239.539 | E12: =CaseDataTable[[#This Row],[Время]] -> 46239.539
A13: 126 | B13: 8745 | C13: ML старт | D13: 46239.557 | E13: =CaseDataTable[[#This Row],[Время]] -> 46239.557
A14: 225 | B14: 8745 | C14: АВ тестам | D14: 46239.599 | E14: =CaseDataTable[[#This Row],[Время]] -> 46239.599
... A796: 196 | B796: 9950 | C796: Линейная алгебра | D796: 46275.256 | E796: =CaseDataTable[[#This Row],[Время]] -> 46275.256

Sheet общее
A3: Сумма по полю Сумма | B3: Названия столбцов
A4: Названия строк | B4: АВ тестам | C4: Алгоритмы | D4: Алгоритмы про | E4: Алгоритмы старт | F4: Аналитика про | G4: Аналитика старт | H4: Дискретка | I4: К ВУЗу | J4: Линейная алгебра | K4: Мат анализ | L4: Теория вероятностей | M4: AI агенты | N4: Backend про | O4: Backend старт | P4: Data Engenering | Q4: Data Science | R4: ML про | S4: ML старт | T4: Общий итог
A5: 04.авг | G5: 7890 | I5: 8950 | J5: 8475 | K5: 8475 | O5: 8745 | Q5: 15695 | R5: 17425 | S5: 8475 | T5: 84130
A6: 05.авг | B6: 8745 | N6: 16450 | O6: 24925 | S6: 16990 | T6: 67110
A7: 06.авг | I7: 13900 | J7: 29850 | K7: 9950 | L7: 500 | S7: 8245 | T7: 62445
A8: 07.авг | I8: 6950 | J8: 9950 | K8: 29350 | R8: 8745 | T8: 54995
A9: 08.авг | B9: 4495 | C9: 29390 | E9: 72565 | F9: 4995 | G9: 39360 | N9: 16490 | O9: 45850 | P9: 4995 | R9: 8745 | S9: 48130 | T9: 275015
A10: 09.авг | C10: 60625 | E10: 142186.68 | F10: 4950 | G10: 100770 | N10: 6490 | O10: 67226.66 | P10: 6450 | Q10: 19350 | R10: 8745 | S10: 107298.33 | T10: 524091.67
A11: 10.авг | C11: 16185 | E11: 36190 | F11: 14400 | G11: 63830 | I11: 26800 | O11: 9650 | P11: 13400 | S11: 25135 | T11: 205590
A12: 11.авг | E12: 19800 | F12: 3245 | G12: 9735 | I12: 26800 | R12: 8475 | S12: 28275 | T12: 96330
A13: 12.авг | C13: 4950 | D13: 4950 | E13: 4950 | F13: 8475 | G13: 32455 | I13: 19850 | S13: 39300 | T13: 114930
A14: 13.авг | C14: 5750 | E14: 17490 | F14: 17220 | I14: 6450 | L14: 19900 | S14: 6000 | T14: 72810
A15: 14.авг | B15: 4495 | C15: 5750 | E15: 8745 | I15: 20850 | L15: 19900 | R15: 8475 | S15: 8475 | T15: 76690
A16: 15.авг | C16: 18425 | E16: 2875 | G16: 8745 | I16: 6950 | S16: 11350 | T16: 48345
A17: 16.авг | E17: 8745 | F17: 4950 | G17: 22440 | I17: 6950 | T17: 43085
A18: 17.авг | E18: 8745 | I18: 6950 | S18: 17490 | T18: 33185
A19: 18.авг | F19: 8475 | G19: 34440 | J19: 9450 | S19: 8745 | T19: 61110
A20: 19.авг | E20: 16490 | F20: 8245 | G20: 8245 | J20: 9450 | N20: 7000 | Q20: 6950 | T20: 56380
A21: 20.авг | E21: 8745 | G21: 8745 | I21: 6950 | J21: 9450 | L21: 9950 | S21: 8745 | T21: 52585
A22: 21.авг | F22: 8245 | J22: 9950 | K22: 9950 | T22: 28145
A23: 22.авг | C23: 18400 | D23: 37350 | E23: 14950 | F23: 15925 | G23: 25375 | I23: 6950 | J23: 9950 | M23: 38800 | N23: 37375 | R23: 37125 | S23: 8950 | T23: 251150
A24: 23.авг | C24: 16900 | D24: 15425 | F24: 83675 | G24: 38145 | I24: 8000 | M24: 120450 | N24: 41775 | O24: 8950 | R24: 52225 | S24: 8950 | T24: 394495
A25: 24.авг | D25: 14450 | E25: 23900 | F25: 35800 | J25: 9950 | L25: 9950 | M25: 42100.5 | N25: 8222.5 | Q25: 6950 | R25: 14950 | S25: 17800 | T25: 184073
A26: 25.авг | B26: 7475 | F26: 15925 | G26: 8450 | M26: 63725 | N26: 14950 | O26: 8950 | R26: 22175 | T26: 141650
A27: 26.авг | D27: 8950 | F27: 7475 | G27: 8950 | M27: 25850 | N27: 7475 | O27: 7475 | R27: 8950 | S27: 8950 | T27: 84075
A28: 27.авг | C28: 7462.5 | F28: 7475 | K28: 17412.5 | L28: 7462.5 | M28: 39812.5 | N28: 7475 | R28: 21425 | S28: 28900 | T28: 137425
A29: 28.авг | E29: 7475 | G29: 17900 | K29: 9950 | M29: 8950 | O29: 8450 | R29: 7475 | T29: 60200
A30: 29.авг | B30: 5975 | F30: 4475 | G30: 10450 | K30: 9450 | M30: 23875 | N30: 8950 | R30: 32350 | T30: 95525
A31: 30.авг | D31: 13950 | E31: 14450 | F31: 22900 | M31: 68815 | O31: 25375 | R31: 30850 | T31: 176340
A32: 31.авг | D32: 14450 | E32: 21925 | F32: 60171.5 | G32: 16446.5 | H32: 8975 | M32: 33420 | N32: 26875 | O32: 7475 | R32: 7475 | S32: 8975 | T32: 206188
A33: 01.сент | C33: 8245 | D33: 7475 | F33: 44735 | G33: 26870 | H33: 8245 | J33: 8245 | K33: 8245 | L33: 8245 | M33: 31350 | N33: 7475 | R33: 29400 | S33: 38350 | T33: 226880
A34: 02.сент | B34: 5975 | C34: 4225 | D34: 22425 | E34: 32850 | F34: 35285 | G34: 13450 | J34: 18195 | K34: 10000 | L34: 9450 | N34: 57950 | R34: 7475 | T34: 217280
A35: 03.сент | B35: 5975 | D35: 15925 | F35: 51725 | G35: 13450 | I35: 6950 | L35: 18900 | M35: 10000 | N35: 23650 | R35: 33825 | T35: 180400
A36: 04.сент | D36: 7000 | F36: 73650 | G36: 40325 | H36: 8245 | J36: 19900 | M36: 23400 | N36: 34315 | R36: 31375 | S36: 31375 | T36: 269585
A37: 05.сент | B37: 6475 | D37: 34334 | E37: 15950 | F37: 91050 | G37: 37850 | M37: 25850 | N37: 57225 | O37: 23900 | R37: 177100 | S37: 14950 | T37: 484684
A38: 06.сент | D38: 8950 | E38: 13425 | F38: 63725 | G38: 38350 | K38: 29850 | M38: 77125 | N38: 58200 | O38: 7475 | Q38: 6950 | R38: 78600 | S38: 13425 | T38: 396075
A39: 07.сент | C39: 4225 | D39: 25375 | E39: 7475 | F39: 8950 | K39: 9950 | L39: 18900 | M39: 49250 | O39: 8950 | R39: 40300 | T39: 173375
A40: 08.сент | D40: 7500 | E40: 7500 | F40: 8950 | K40: 19900 | M40: 6975 | Q40: 6950 | R40: 6975 | T40: 64750
A41: 09.сент | C41: 8950 | D41: 29900 | E41: 22425 | F41: 25850 | G41: 8950 | H41: 8950 | J41: 17900 | K41: 18900 | L41: 8950 | M41: 21925 | Q41: 6450 | R41: 14450 | T41: 193600
A42: 10.сент | J42: 9950 | T42: 9950
...

Sheet анализ репостов постов 
B4: Дата | C4: Каналы | D4: Кол-во Подписчиков | E4: Кол-во Просмотров | F4: Просм/Подписч | G4: Статус
B5: 46242 | C5: https://t.me/chad_protocol/510 | D5: 10913 | E5: 6855 | F5: =E5/D5 *100 -> 62.814991 | G5: пост
B6: 46242 | C6: https://t.me/postypashki_mems/1373 | D6: 5836 | E6: 1837 | F6: =E6/D6 *100 -> 31.477039 | G6: репост
B7: 46242 | C7: https://tgstat.ru/channel/@analytess/925 | D7: 3478 | E7: 1216 | F7: =E7/D7 *100 -> 34.962622 | G7: репост | H7: удален
B8: 46242 | C8: https://t.me/zadachi_ds/389 | D8: 8078 | E8: 4481 | F8: =E8/D8 *100 -> 55.471651 | G8: пост
B9: 46242 | C9: https://t.me/codeof_art/306 | D9: 2059 | E9: 498 | F9: =E9/D9 *100 -> 24.186498 | G9: репост
B10: 46242 | C10: https://t.me/algoses/594 | D10: 11974 | E10: 1328 | F10: =E10/D10 *100 -> 11.090697 | G10: репост
B11: 46242 | C11: https://tgstat.ru/channel/@matesha_shad/373 | D11: 5008 | E11: 1757 | F11: =E11/D11 *100 -> 35.083866 | G11: репост | H11: удален 27 авг
B12: 46242 | C12: https://tgstat.ru/channel/@zadachi_ds/390 | D12: 8077 | E12: 4481 | F12: =E12/D12 *100 -> 55.478519 | G12: репост | H12: удален 2 сен
B13: 46243 | C13: https://tgstat.ru/channel/@zadachi_ds/392 | D13: 8097 | E13: 2108 | F13: =E13/D13 *100 -> 26.034334 | G13: репост
B14: 46243 | C14: https://tgstat.ru/channel/@zadachi_ds/391 | G14: пост
B15: 46243
B16: 46243

Sheet Сумма Продаж Каждый День
A2: Дата | B2: Сумма продаж за день
A3: 04.авг | B3: 84130
A4: 05.авг | B4: 67110
A5: 06.авг | B5: 62445
A6: 07.авг | B6: 54995
A7: 08.авг | B7: 275015
A8: 09.авг | B8: 524091.67
A9: 10.авг | B9: 205590
A10: 11.авг | B10: 96330
A11: 12.авг | B11: 114930
A12: 13.авг | B12: 72810
A13: 14.авг | B13: 76690
A14: 15.авг | B14: 48345
... A25: 26.авг | B25: 84075
A26: 27.авг | B26: 137425 | D26: Видны три всплеска: 8–10 августа (пик 9 августа, ~524 тыс. ₽), 22–24 августа (пик 23 августа, ~394 тыс. ₽) и 4–6 сентября (пик 5 сентября, ~485 тыс. ₽). Вся выручка за период — около 5,9 млн ₽.
A27: 28.авг | B27: 60200
A28: 29.авг | B28: 95525
A29: 30.авг | B29: 176340
A30: 31.авг | B30: 206188
A31: 01.сент | B31: 226880
A32: 02.сент | B32: 217280
A33: 03.сент | B33: 180400
A34: 04.сент | B34: 269585
A35: 05.сент | B35: 484684
A36: 06.сент | B36: 396075
A37: 07.сент | B37: 173375
A38: 08.сент | B38: 64750
... A40: 10.сент | B40: 9950

Sheet Кол-Во Подписчиков
A1: График подписчиков | B1: кол-во подписчкиво | C1: дельта (ежедневное изменение)
A2: 46235 | B2: 43126 | C2: 0 | E2: Вывод по графику: Обычно канал получает от +10 до +60 подписчиков в день. Пики: 10 августа (+119), 14 августа (+121), 26 и 30 августа (+82, +86), 8 сентября (+87). 15 августа прирост был −15, то есть отписок оказалось больше, чем подписок. Главное: пики подписчиков не совпадают с пиками продаж, корреляция ≈ 0 даже со сдвигом до недели. Похоже, покупает уже существующая аудитория канала (~43 тыс.), а новые подписчики сразу не покупают. Проверить это нельзя, потому что мы не знаем, когда покупатель подписался.
A3: 46236 | B3: 43144 | C3: =B3-B2 -> 18
A4: 46237 | B4: 43175 | C4: =B4-B3 -> 31
A5: 46238 | B5: 43186 | C5: =B5-B4 -> 11
A6: 46239 | B6: 43204 | C6: =B6-B5 -> 18
A7: 46240 | B7: 43221 | C7: =B7-B6 -> 17
A8: 46241 | B8: 43230 | C8: =B8-B7 -> 9
A9: 46242 | B9: 43272 | C9: =B9-B8 -> 42
A10: 46243 | B10: 43302 | C10: =B10-B9 -> 30
A11: 46244 | B11: 43421 | C11: =B11-B10 -> 119
A12: 46245 | B12: 43445 | C12: =B12-B11 -> 24
A13: 46246 | B13: 43493 | C13: =B13-B12 -> 48
A14: 46247 | B14: 43530 | C14: =B14-B13 -> 37
... A35: 46268 | B35: 44550 | C35: =B35-B34 -> 55
A36: 46269 | B36: 44602 | C36: =B36-B35 -> 52 | E36: Пики | F36: 46244 | G36: 46248 | H36: 46275 | I36: 46273 | J36: 46264
A37: 46270 | B37: 44634 | C37: =B37-B36 -> 32
A38: 46271 | B38: 44651 | C38: =B38-B37 -> 17
A39: 46272 | B39: 44688 | C39: =B39-B38 -> 37
A40: 46273 | B40: 44775 | C40: =B40-B39 -> 87
A41: 46274 | B41: 44829 | C41: =B41-B40 -> 54
A42: 46275 | B42: 44927 | C42: =B42-B41 -> 98

Sheet Покупатели и Медиан цена
A1: Дата | B1: Покупатели | C1: Медианная цена
A2: 46238 | B2: {=COUNTA(_xlfn.UNIQUE(_xlfn._xlws.FILTER(Данные!$A$2:$A$796,INT(Данные!$D$2:$D$796)=A2)))} -> 6 | C2: {=MEDIAN(_xlfn._xlws.FILTER(Данные!$B$2:$B$796,INT(Данные!$D$2:$D$796)='Покупатели и Медиан цена'!A2))} -> 8475
A3: 46239 | B3: {=COUNTA(_xlfn.UNIQUE(_xlfn._xlws.FILTER(Данные!$A$2:$A$796,INT(Данные!$D$2:$D$796)=A3)))} -> 6 | C3: {=MEDIAN(_xlfn._xlws.FILTER(Данные!$B$2:$B$796,INT(Данные!$D$2:$D$796)='Покупатели и Медиан цена'!A3))} -> 8475
A4: 46240 | B4: {=COUNTA(_xlfn.UNIQUE(_xlfn._xlws.FILTER(Данные!$A$2:$A$796,INT(Данные!$D$2:$D$796)=A4)))} -> 7 | C4: {=MEDIAN(_xlfn._xlws.FILTER(Данные!$B$2:$B$796,INT(Данные!$D$2:$D$796)='Покупатели и Медиан цена'!A4))} -> 9097.5
A5: 46241 | B5: {=COUNTA(_xlfn.UNIQUE(_xlfn._xlws.FILTER(Данные!$A$2:$A$796,INT(Данные!$D$2:$D$796)=A5)))} -> 5 | C5: {=MEDIAN(_xlfn._xlws.FILTER(Данные!$B$2:$B$796,INT(Данные!$D$2:$D$796)='Покупатели и Медиан цена'!A5))} -> 9700
A6: 46242 | B6: {=COUNTA(_xlfn.UNIQUE(_xlfn._xlws.FILTER(Данные!$A$2:$A$796,INT(Данные!$D$2:$D$796)=A6)))} -> 35 | C6: {=MEDIAN(_xlfn._xlws.FILTER(Данные!$B$2:$B$796,INT(Данные!$D$2:$D$796)='Покупатели и Медиан цена'!A6))} -> 4995
A7: 46243 | B7: {=COUNTA(_xlfn.UNIQUE(_xlfn._xlws.FILTER(Данные!$A$2:$A$796,INT(Данные!$D$2:$D$796)=A7)))} -> 68 | C7: {=MEDIAN(_xlfn._xlws.FILTER(Данные!$B$2:$B$796,INT(Данные!$D$2:$D$796)='Покупатели и Медиан цена'!A7))} -> 4995
A8: 46244 | B8: {=COUNTA(_xlfn.UNIQUE(_xlfn._xlws.FILTER(Данные!$A$2:$A$796,INT(Данные!$D$2:$D$796)=A8)))} -> 29 | C8: {=MEDIAN(_xlfn._xlws.FILTER(Данные!$B$2:$B$796,INT(Данные!$D$2:$D$796)='Покупатели и Медиан цена'!A8))} -> 4972.5
A9: 46245 | B9: {=COUNTA(_xlfn.UNIQUE(_xlfn._xlws.FILTER(Данные!$A$2:$A$796,INT(Данные!$D$2:$D$796)=A9)))} -> 12 | C9: {=MEDIAN(_xlfn._xlws.FILTER(Данные!$B$2:$B$796,INT(Данные!$D$2:$D$796)='Покупатели и Медиан цена'!A9))} -> 4950
A10: 46246 | B10: {=COUNTA(_xlfn.UNIQUE(_xlfn._xlws.FILTER(Данные!$A$2:$A$796,INT(Данные!$D$2:$D$796)=A10)))} -> 14 | C10: {=MEDIAN(_xlfn._xlws.FILTER(Данные!$B$2:$B$796,INT(Данные!$D$2:$D$796)='Покупатели и Медиан цена'!A10))} -> 6490
A11: 46247 | B11: {=COUNTA(_xlfn.UNIQUE(_xlfn._xlws.FILTER(Данные!$A$2:$A$796,INT(Данные!$D$2:$D$796)=A11)))} -> 9 | C11: {=MEDIAN(_xlfn._xlws.FILTER(Данные!$B$2:$B$796,INT(Данные!$D$2:$D$796)='Покупатели и Медиан цена'!A11))} -> 8745
A12: 46248 | B12: {=COUNTA(_xlfn.UNIQUE(_xlfn._xlws.FILTER(Данные!$A$2:$A$796,INT(Данные!$D$2:$D$796)=A12)))} -> 9 | C12: {=MEDIAN(_xlfn._xlws.FILTER(Данные!$B$2:$B$796,INT(Данные!$D$2:$D$796)='Покупатели и Медиан цена'!A12))} -> 7712.5
A13: 46249 | B13: {=COUNTA(_xlfn.UNIQUE(_xlfn._xlws.FILTER(Данные!$A$2:$A$796,INT(Данные!$D$2:$D$796)=A13)))} -> 5 | C13: {=MEDIAN(_xlfn._xlws.FILTER(Данные!$B$2:$B$796,INT(Данные!$D$2:$D$796)='Покупатели и Медиан цена'!A13))} -> 8475
... A38: 46274 | B38: {=COUNTA(_xlfn.UNIQUE(_xlfn._xlws.FILTER(Данные!$A$2:$A$796,INT(Данные!$D$2:$D$796)=A38)))} -> 16 | C38: {=MEDIAN(_xlfn._xlws.FILTER(Данные!$B$2:$B$796,INT(Данные!$D$2:$D$796)='Покупатели и Медиан цена'!A38))} -> 7475
A53: • 8–10 августа: 35 → 68 → 29 покупателей при норме ~6, а цена упала с ~8 500–9 700 до ~5 000 ₽. Это похоже на скидку на курсы линейки «старт» (ML про при этом не дешевел). В тот же день было 9 внешних упоминаний канала и появились новые курсы, так что вклад каждого фактора разделить нельзя. • 22–24 августа: 26 → 39 → 19 покупателей, цена обычная. Совпадает с первыми продажами курса «AI агенты», вероятно это запуск. • 4–6 сентября: 26 → 48 → 45 покупателей, цена обычная. 5 сентября много продаж ML про. Причина пока неизвестна, нужно искать пост или акцию.
